<?xml version="1.0"?>
<robot     xmlns:xacro="http://playerstage.sourceforge.net/gazebo/xmlschema/#interface">
  
  <property name="base_size_x" value="0.92"/>
  <property name="base_size_y" value="0.24"/>
  <property name="base_size_z" value="0.34"/>
  <property name="M_PI" value="3.14159265359"/>
  
  <xacro:include filename="$(find hector_xacro_tools)/urdf/inertia_tensors.urdf.xacro" />  
  
  <macro name="taurob_arm_macro" params="parent *origin">
    
    
    <joint name="arm_joint_0" type="revolute">    
      <insert_block name="origin"/>
      <axis xyz="0 0 1"/>
      <limit lower="${-180 * M_PI / 180}" upper="${180 * M_PI / 180}" effort="1000" velocity="${1.0 * 110 * M_PI / 180}"/>
      <!--        <safety_controller soft_lower_limit="${-168 * M_PI / 180}"
      soft_upper_limit="${168 * M_PI / 180}"
      k_position="${100}"
      k_velocity="${2}"/>-->
      
      <parent link="${parent}"/>
      <child link="arm_link_0"/>
    </joint>
    
    <link name="arm_link_0">
      <xacro:inertial_cuboid_with_pose mass="4.0" x_length="0.08" y_length="${0.08}" z_length="0.137" >
        <origin xyz="0.0 0.0 ${0.137*0.5}" rpy="0 0 0" />
      </xacro:inertial_cuboid_with_pose>      
      <visual>
        <origin xyz="0.0 0.0 0.0" rpy="0 0 ${M_PI / 2}"/>
        <geometry>
          <mesh filename="package://taurob_arm_description/meshes/tarm_link_0.stl"/>
        </geometry>
        <material name="DarkGrey">
          <color rgba="0.3 0.3 0.3 1"/>
        </material>                
      </visual>
      
      <arm_link_0_collision_geom_marco/>
    </link>
    
    <joint name="arm_joint_1" type="revolute">    
      <origin xyz="-0.052 0.0 0.1" rpy="0 0 0"/>
      <axis xyz="1 0 0"/>
      <limit lower="${0 * M_PI / 180}" upper="${180 * M_PI / 180}" effort="1000" velocity="${1.0 * 110 * M_PI / 180}"/>
      <!--        <safety_controller soft_lower_limit="${-168 * M_PI / 180}"
      soft_upper_limit="${168 * M_PI / 180}"
      k_position="${100}"
      k_velocity="${2}"/>-->
      
      <parent link="arm_link_0"/>
      <child link="arm_link_1"/>
    </joint>
    
    <link name="arm_link_1">
      <xacro:inertial_cuboid_with_pose mass="4.0" x_length="0.073" y_length="${0.4}" z_length="0.086" >
        <origin xyz="-0.045 0.18 0.0" rpy="0 0 0" />
      </xacro:inertial_cuboid_with_pose> 
      
      <visual>
        <origin xyz="0.0 0.0 0.0" rpy="0 0 0"/>
        <geometry>
          <mesh filename="package://taurob_arm_description/meshes/tarm_link_1.stl"/>
        </geometry>
        <material name="DarkGrey">
          <color rgba="0.3 0.3 0.3 1"/>
        </material>                
      </visual>
      
      <arm_link_1_collision_geom_marco/>
    </link>
    
    <joint name="arm_joint_2" type="revolute">    
      <origin xyz="0.003 0.55 0.03" rpy=" 0 0 0"/>
      <axis xyz="-1 0 0"/>
      <limit lower="${0 * M_PI / 180}" upper="${180 * M_PI / 180}" effort="1000" velocity="${1.0 * 110 * M_PI / 180}"/>
      <!--        <safety_controller soft_lower_limit="${-168 * M_PI / 180}"
      soft_upper_limit="${168 * M_PI / 180}"
      k_position="${100}"
      k_velocity="${2}"/>-->
      
      <parent link="arm_link_1"/>
      <child link="arm_link_2"/>
    </joint>
    
    <link name="arm_link_2">
      <xacro:inertial_cuboid_with_pose mass="4.0" x_length="0.073" y_length="${0.6}" z_length="0.086" >
        <origin xyz="${-0.073*0.5} 0.28 0.0" rpy="0 0 0" />
      </xacro:inertial_cuboid_with_pose> 
      
      <visual>
        <origin xyz="0.0 0.0 0.0" rpy="0 0 0"/>
        <geometry>
          <mesh filename="package://taurob_arm_description/meshes/tarm_link_2.stl"/>
        </geometry>
        <material name="DarkGrey">
          <color rgba="0.3 0.3 0.3 1"/>
        </material>                
      </visual>
      
      <arm_link_2_collision_geom_marco/>
    </link>
    
    <joint name="arm_joint_3" type="revolute">    
      <origin xyz="0.096 -0.42 0" rpy=" 0 0 0"/>
      <axis xyz="-1 0 0"/>
      <limit lower="${-180 * M_PI / 180}" upper="${180 * M_PI / 180}" effort="1000" velocity="${1.0 * 110 * M_PI / 180}"/>
      <!--        <safety_controller soft_lower_limit="${-168 * M_PI / 180}"
      soft_upper_limit="${168 * M_PI / 180}"
      k_position="${100}"
      k_velocity="${2}"/>-->
      
      <parent link="arm_link_2"/>
      <child link="arm_link_3"/>
    </joint>
    
    <link name="arm_link_3">
      <xacro:inertial_cuboid_with_pose mass="4.0" x_length="0.1" y_length="${0.2}" z_length="0.18" >
        <origin xyz="0.1 0.05 0.08" rpy="0 0 0" />
      </xacro:inertial_cuboid_with_pose> 
      
      <visual>
        <origin xyz="0.0 0.0 0.0" rpy="0 0 0"/>
        <geometry>
          <mesh filename="package://taurob_arm_description/meshes/tarm_link_3.stl"/>
        </geometry>
        <material name="DarkGrey">
          <color rgba="0.3 0.3 0.3 1"/>
        </material>                
      </visual>
      
      <arm_link_3_collision_geom_marco/>
    </link>        
    
    <!--Needed for simulation-->
    <transmission name="arm_joint_0_joint_transmssion">
      <type>transmission_interface/SimpleTransmission</type>
      <joint name="arm_joint_0">
        <hardwareInterface>EffortJointInterface</hardwareInterface>
      </joint>        
      <actuator name="arm_joint_0_motor">
        <hardwareInterface>EffortJointInterface</hardwareInterface>
        <mechanicalReduction>1</mechanicalReduction>
      </actuator>
    </transmission>
    
    <transmission name="arm_joint_1_joint_transmssion">
      <type>transmission_interface/SimpleTransmission</type>
      <joint name="arm_joint_1">
        <hardwareInterface>EffortJointInterface</hardwareInterface>
      </joint>  
      <actuator name="arm_joint_1_motor">
        <hardwareInterface>EffortJointInterface</hardwareInterface>
        <mechanicalReduction>1</mechanicalReduction>
      </actuator>
    </transmission>
    
    <transmission name="arm_joint_2_joint_transmssion">
      <type>transmission_interface/SimpleTransmission</type>
      <joint name="arm_joint_2">
        <hardwareInterface>EffortJointInterface</hardwareInterface>
      </joint>  
      <actuator name="arm_joint_2_motor">
        <hardwareInterface>EffortJointInterface</hardwareInterface>
        <mechanicalReduction>1</mechanicalReduction>
      </actuator>
    </transmission>
    
    <transmission name="arm_joint_3_joint_transmssion">
      <type>transmission_interface/SimpleTransmission</type>
      <joint name="arm_joint_3">
        <hardwareInterface>EffortJointInterface</hardwareInterface>
      </joint>        
      <actuator name="arm_joint_3_motor">
        <hardwareInterface>EffortJointInterface</hardwareInterface>
        <mechanicalReduction>1</mechanicalReduction>
      </actuator>
    </transmission> 
    
    <gazebo reference="arm_link_0">
      <material>Gazebo/Grey</material>
    </gazebo>   
    
    <gazebo reference="arm_link_1">
      <material>Gazebo/Grey</material>
    </gazebo>  
    
    <gazebo reference="arm_link_2">
      <material>Gazebo/Grey</material>
    </gazebo>  
    
    <gazebo reference="arm_link_3">
      <material>Gazebo/Grey</material>
    </gazebo>  
    
  </macro>
</robot>
